<?xml version="1.0"?>

<robot name="apfbot" xmlns:xacro="http://ros.org/wiki/xacro">

    <xacro:include filename="common_properties.xacro" />
    <xacro:include filename="$(find apf_description)/urdf/apf_gazebo.xacro"/>

    <!-- ROS2 control -->
    <xacro:include filename="$(find apf_description)/urdf/apf_ros2_control.xacro"/>

    <material name="blue">
        <color rgba="0 0 0.8 1"/>
    </material>
    <material name="grey">
        <color rgba="0.4 0.4 0.4 1"/>
    </material>

    <link name="base_footprint"/>

    <link name="base_link">
        <inertial>
            <origin xyz="0 0 0.04" rpy="0.0 0.25 0.3" />
            <mass value="8.2573504e-01"/>
            <inertia ixx="2.2124416e-02" ixy="-1.2294101e-04" ixz="3.4938785e-04"
                     iyy="2.1193702e-02" iyz="-5.0120904e-05"
                     izz="2.0064271e-02" />            
        </inertial>
        <visual>
            <origin rpy="0 0 0" xyz="0 0 0"/>
            <geometry>
                <mesh filename="package://apf_description/meshes/base_link.STL"/>
            </geometry>
            <material name="blue"/>
        </visual>
        <collision>
            <origin rpy="0 0 0" xyz="0 0 0"/>
            <geometry>
                <mesh filename="package://apf_description/meshes/base_link.STL"/>
            </geometry>
        </collision>
    </link>
    <joint name="base_joint" type="fixed">
        <parent link="base_footprint"/>
        <child link="base_link"/>
        <origin rpy="0 0 0" xyz="0 0 0.033"/>
    </joint>


    <link name="wheel_left_link">
        <inertial>
            <origin xyz="0 0.014 0" rpy="0 0 0" />
            <mass value="0.0530086043217644" />
            <inertia ixx="1.8792911368909E-05"  ixy="3.31256392204584E-10" ixz="-1.14082001662767E-08"
                     iyy="3.11510738759073E-05" iyz="-3.60499245082192E-10"
                     izz="1.88266886146847E-05" />
        </inertial>        
        <visual>
            <origin rpy="-${pi / 2.0} 0 0" xyz="0 0 0"/>
            <geometry>
                <mesh filename="package://apf_description/meshes/wheel_left_link.STL"/>
            </geometry>
            <material name="grey"/>
        </visual>
        <collision>
            <origin xyz="0 0.015 0" rpy="${pi / 2.0} 0 0"/>
            <geometry>
                <sphere radius="0.033"/>
            </geometry>
        </collision>
    </link>
    <joint name="wheel_left_joint" type="continuous">
        <parent link="base_link"/>
        <child link="wheel_left_link"/>
        <axis xyz="0 1 0"/>
        <origin rpy="0 0 0" xyz="0 0.07 0"/>
    </joint>


    <link name="wheel_right_link">
        <inertial>
            <origin xyz="0 -0.014 0" rpy="0 0 0" />
            <mass value="0.0530086090966721" />
            <inertia ixx="1.88176298336665E-05" ixy="-4.8444933029987E-10" ixz="1.88163708851143E-08"
                     iyy="3.11510738647764E-05" iyz="-6.93560663069607E-11"
                     izz="1.8801969558182E-05" />
              </inertial>        
        <visual>
            <origin rpy="${pi / 2.0} 0 0" xyz="0 0 0"/>
            <geometry>
                <mesh filename="package://apf_description/meshes/wheel_right_link.STL"/>
            </geometry>
            <material name="grey"/>
        </visual>
        <collision>
            <origin xyz="0 -0.015 0" rpy="${pi / 2.0} 0 0"/>
            <geometry>
                <sphere radius="0.033"/>
            </geometry>
        </collision>
    </link>
    <joint name="wheel_right_joint" type="continuous">
        <parent link="base_link"/>
        <child link="wheel_right_link"/>
        <axis xyz="0 1 0"/>
        <origin rpy="0 0 0" xyz="0 -0.07 0"/>
    </joint> 
  

    <link name="caster_front_link">
        <inertial>
            <origin xyz="3.89968128948481E-07 2.40073004698083E-07 0.00219173397061506" rpy="0 0 0" />
            <mass value="1.44379265037903E-06" />
            <inertia ixx="7.23075276010246E-11" ixy="-6.10956883467859E-16" ixz="2.22849693525031E-15"
                     iyy="3.8713793085917E-11"  iyz="2.93909858781952E-15"
                     izz="1.00967486676306E-10" />
        </inertial>    
        <visual>
            <origin rpy="0 0 0" xyz="0 0 0"/>
            <geometry>
                <mesh filename="package://apf_description/meshes/caster_front_link.STL"/>
            </geometry> 
        </visual>
        <collision>
            <origin xyz="0 0 0" rpy="0 0 0"/>
            <geometry>
                <sphere radius="0.005"/>
            </geometry>
        </collision>                
    </link>
    <joint name="caster_front_joint" type="fixed">
        <parent link="base_link"/>
        <child link="caster_front_link"/>
        <origin rpy="0 0 0" xyz="0.04755 0 -0.0275"/>
    </joint> 

    <link name="caster_rear_link">
        <inertial>
            <origin xyz="3.8996812895542E-07 2.40073004698083E-07 0.00219173397061509" rpy="0 0 0" />
            <mass value="1.44379265037902E-06" />
            <inertia ixx="7.23075276010246E-11" ixy="-6.10956872363424E-16" ixz="2.22849693527207E-15"
                     iyy="3.87137930859167E-11" iyz="2.939098587861E-15"
                     izz="1.00967486676306E-10" />
        </inertial>    
        <visual>
            <origin rpy="0 0 0" xyz="0 0 0"/>
            <geometry>
                <mesh filename="package://apf_description/meshes/caster_rear_link.STL"/>
            </geometry> 
        </visual>
        <collision>
            <origin xyz="0 0 0" rpy="0 0 0"/>
            <geometry>
                <sphere radius="0.005"/>
            </geometry>
        </collision>        
    </link>
    <joint name="caster_rear_joint" type="fixed">
        <parent link="base_link"/>
        <child link="caster_rear_link"/>
        <origin rpy="0 0 0" xyz="-0.04755 0 -0.0275"/>
    </joint> 


    <link name="lidar_link">
        <visual>
            <origin xyz="0 0 0.089" rpy="0 0 0"/>
            <geometry>
                <box size="0.02 0.02 0.02" />
            </geometry>
        </visual>
        <collision>
            <origin xyz="0 0 0.089" rpy="0 0 0"/>
            <geometry>
                <box size="0.02 0.02 0.02" />
            </geometry>   
        </collision>
        <inertial>
            <origin xyz="0 0 0.089" rpy="0 0 0"/>
            <mass value="1"/>
            <inertia ixx="1.0" ixy="0.0" ixz="0.0"
                     iyy="1.0" iyz="0.0"
                     izz="1.0"/>
        </inertial>
    </link>

    <joint name='lidar_sensor_joint' type='fixed'>
		<parent link="base_link"/>
		<child link="lidar_link"/>
    </joint>




    <!-- Wheels -->
    <!-- <gazebo reference="wheel_right_link">
        <mu1>100000000000000.0</mu1>
        <mu2>100000000000000.0</mu2>
        <kp>1000000000000.0</kp>
        <kd>10.0</kd>
        <minDepth>0.001</minDepth>
        <maxVel>0.1</maxVel>
        <fdir1>1 0 0</fdir1>
    </gazebo>

    <gazebo reference="wheel_left_link">
        <mu1>100000000000000.0</mu1>
        <mu2>100000000000000.0</mu2>
        <kp>1000000000000.0</kp>
        <kd>10.0</kd>
        <minDepth>0.001</minDepth>
        <maxVel>0.1</maxVel>
        <fdir1>1 0 0</fdir1>
    </gazebo> -->

    <!-- Caster Wheels -->
    <!-- <gazebo reference="caster_front_link">
        <mu1>0.1</mu1>
        <mu2>0.1</mu2>
        <kp>1000000.0</kp>
        <kd>100.0</kd>
        <minDepth>0.001</minDepth>
        <maxVel>0.1</maxVel>
    </gazebo>

    <gazebo reference="caster_rear_link">
        <mu1>0.1</mu1>
        <mu2>0.1</mu2>
        <kp>1000000.0</kp>
        <kd>100.0</kd>
        <minDepth>0.001</minDepth>
        <maxVel>0.1</maxVel>
    </gazebo> -->

    <!-- configure LIDAR -->
    <!-- <gazebo reference="lidar_link">
		<sensor name="lidar" type='gpu_lidar'>
			<pose>0 0 0.1 0 0 0</pose>
            <topic>lidar</topic>
            <update_rate>10</update_rate>
            <ray>
                <scan>
                    <horizontal>
                        <samples>640</samples>
                        <resolution>1</resolution>
                        <min_angle>-1.396263</min_angle>
                        <max_angle>1.396263</max_angle>
                    </horizontal>
                    <vertical>
                        <samples>16</samples>
                        <resolution>1</resolution>
                        <min_angle>-0.261799</min_angle>
                        <max_angle>0.261799</max_angle>
                    </vertical>
                </scan>
                <range> -->
                    <!-- <min>0.08</min> -->
                    <!-- <min>0.1</min>
                    <max>10.0</max>
                    <resolution>0.01</resolution>
                </range>
            </ray>
            <always_on>1</always_on>
            <visualize>true</visualize>
			<gz_frame_id>lidar_link</gz_frame_id>
            <plugin filename="libignition-gazebo-sensors-system.so" name="ignition::gazebo::systems::Sensors">
				<render_engine>ogre2</render_engine>
			</plugin>			
		</sensor>
	</gazebo> -->

    <!--  ROS2 control  -->
    <!-- <gazebo> -->
        <!-- <plugin filename="ign_ros2_control-system" name="ign_ros2_control::IgnitionROS2ControlPlugin">
                <parameters>$(find apf_control)/config/apf_controllers.yaml</parameters>
        </plugin> -->

        <!-- <plugin
          filename="libignition-gazebo-diff-drive-system.so"
          name="ignition::gazebo::systems::DiffDrive">
          <left_joint>wheel_left_joint</left_joint>
          <right_joint>wheel_right_joint</right_joint>
          <wheel_separation>0.17</wheel_separation>
          <wheel_radius>0.033</wheel_radius>

          <odom_publish_frequency>10</odom_publish_frequency>
          <topic>cmd_vel</topic>
        	<robotBaseFrame>base_link</robotBaseFrame>
        </plugin>
    </gazebo> -->







</robot>